Exception on /user/F1001 [POST]
Traceback (most recent call last):
  File "/Users/chliu.brook/Documents/Brook/Work/Server/Python/realmServer/venv/lib/python3.6/site-packages/sqlalchemy/engine/base.py", line 1182, in _execute_context
    context)
  File "/Users/chliu.brook/Documents/Brook/Work/Server/Python/realmServer/venv/lib/python3.6/site-packages/sqlalchemy/engine/default.py", line 470, in do_execute
    cursor.execute(statement, parameters)
  File "/Users/chliu.brook/Documents/Brook/Work/Server/Python/realmServer/venv/lib/python3.6/site-packages/pymysql/cursors.py", line 166, in execute
    result = self._query(query)
  File "/Users/chliu.brook/Documents/Brook/Work/Server/Python/realmServer/venv/lib/python3.6/site-packages/pymysql/cursors.py", line 322, in _query
    conn.query(q)
  File "/Users/chliu.brook/Documents/Brook/Work/Server/Python/realmServer/venv/lib/python3.6/site-packages/pymysql/connections.py", line 856, in query
    self._affected_rows = self._read_query_result(unbuffered=unbuffered)
  File "/Users/chliu.brook/Documents/Brook/Work/Server/Python/realmServer/venv/lib/python3.6/site-packages/pymysql/connections.py", line 1057, in _read_query_result
    result.read()
  File "/Users/chliu.brook/Documents/Brook/Work/Server/Python/realmServer/venv/lib/python3.6/site-packages/pymysql/connections.py", line 1340, in read
    first_packet = self.connection._read_packet()
  File "/Users/chliu.brook/Documents/Brook/Work/Server/Python/realmServer/venv/lib/python3.6/site-packages/pymysql/connections.py", line 1014, in _read_packet
    packet.check_error()
  File "/Users/chliu.brook/Documents/Brook/Work/Server/Python/realmServer/venv/lib/python3.6/site-packages/pymysql/connections.py", line 393, in check_error
    err.raise_mysql_exception(self._data)
  File "/Users/chliu.brook/Documents/Brook/Work/Server/Python/realmServer/venv/lib/python3.6/site-packages/pymysql/err.py", line 107, in raise_mysql_exception
    raise errorclass(errno, errval)
pymysql.err.ProgrammingError: (1064, "You have an error in your SQL syntax; check the manual that corresponds to your MySQL server version for the right syntax to use near 'userCode = 'UR20180102210820239320FSFA'' at line 1")

The above exception was the direct cause of the following exception:

Traceback (most recent call last):
  File "/Users/chliu.brook/Documents/Brook/Work/Server/Python/realmServer/venv/lib/python3.6/site-packages/flask/app.py", line 1982, in wsgi_app
    response = self.full_dispatch_request()
  File "/Users/chliu.brook/Documents/Brook/Work/Server/Python/realmServer/venv/lib/python3.6/site-packages/flask/app.py", line 1614, in full_dispatch_request
    rv = self.handle_user_exception(e)
  File "/Users/chliu.brook/Documents/Brook/Work/Server/Python/realmServer/venv/lib/python3.6/site-packages/flask/app.py", line 1517, in handle_user_exception
    reraise(exc_type, exc_value, tb)
  File "/Users/chliu.brook/Documents/Brook/Work/Server/Python/realmServer/venv/lib/python3.6/site-packages/flask/_compat.py", line 33, in reraise
    raise value
  File "/Users/chliu.brook/Documents/Brook/Work/Server/Python/realmServer/venv/lib/python3.6/site-packages/flask/app.py", line 1612, in full_dispatch_request
    rv = self.dispatch_request()
  File "/Users/chliu.brook/Documents/Brook/Work/Server/Python/realmServer/venv/lib/python3.6/site-packages/flask/app.py", line 1598, in dispatch_request
    return self.view_functions[rule.endpoint](**req.view_args)
  File "/Users/chliu.brook/Documents/Brook/Work/Server/Python/realmServer/realmApp/user/views.py", line 23, in getUser
    return UserView.queryUsersSQL(userCode)
  File "/Users/chliu.brook/Documents/Brook/Work/Server/Python/realmServer/realmApp/model/userAction.py", line 44, in queryUsersSQL
    res = session.execute(text(sqlText),sqlDic).fetchall()
  File "/Users/chliu.brook/Documents/Brook/Work/Server/Python/realmServer/venv/lib/python3.6/site-packages/sqlalchemy/orm/session.py", line 1139, in execute
    bind, close_with_result=True).execute(clause, params or {})
  File "/Users/chliu.brook/Documents/Brook/Work/Server/Python/realmServer/venv/lib/python3.6/site-packages/sqlalchemy/engine/base.py", line 945, in execute
    return meth(self, multiparams, params)
  File "/Users/chliu.brook/Documents/Brook/Work/Server/Python/realmServer/venv/lib/python3.6/site-packages/sqlalchemy/sql/elements.py", line 263, in _execute_on_connection
    return connection._execute_clauseelement(self, multiparams, params)
  File "/Users/chliu.brook/Documents/Brook/Work/Server/Python/realmServer/venv/lib/python3.6/site-packages/sqlalchemy/engine/base.py", line 1053, in _execute_clauseelement
    compiled_sql, distilled_params
  File "/Users/chliu.brook/Documents/Brook/Work/Server/Python/realmServer/venv/lib/python3.6/site-packages/sqlalchemy/engine/base.py", line 1189, in _execute_context
    context)
  File "/Users/chliu.brook/Documents/Brook/Work/Server/Python/realmServer/venv/lib/python3.6/site-packages/sqlalchemy/engine/base.py", line 1402, in _handle_dbapi_exception
    exc_info
  File "/Users/chliu.brook/Documents/Brook/Work/Server/Python/realmServer/venv/lib/python3.6/site-packages/sqlalchemy/util/compat.py", line 203, in raise_from_cause
    reraise(type(exception), exception, tb=exc_tb, cause=cause)
  File "/Users/chliu.brook/Documents/Brook/Work/Server/Python/realmServer/venv/lib/python3.6/site-packages/sqlalchemy/util/compat.py", line 186, in reraise
    raise value.with_traceback(tb)
  File "/Users/chliu.brook/Documents/Brook/Work/Server/Python/realmServer/venv/lib/python3.6/site-packages/sqlalchemy/engine/base.py", line 1182, in _execute_context
    context)
  File "/Users/chliu.brook/Documents/Brook/Work/Server/Python/realmServer/venv/lib/python3.6/site-packages/sqlalchemy/engine/default.py", line 470, in do_execute
    cursor.execute(statement, parameters)
  File "/Users/chliu.brook/Documents/Brook/Work/Server/Python/realmServer/venv/lib/python3.6/site-packages/pymysql/cursors.py", line 166, in execute
    result = self._query(query)
  File "/Users/chliu.brook/Documents/Brook/Work/Server/Python/realmServer/venv/lib/python3.6/site-packages/pymysql/cursors.py", line 322, in _query
    conn.query(q)
  File "/Users/chliu.brook/Documents/Brook/Work/Server/Python/realmServer/venv/lib/python3.6/site-packages/pymysql/connections.py", line 856, in query
    self._affected_rows = self._read_query_result(unbuffered=unbuffered)
  File "/Users/chliu.brook/Documents/Brook/Work/Server/Python/realmServer/venv/lib/python3.6/site-packages/pymysql/connections.py", line 1057, in _read_query_result
    result.read()
  File "/Users/chliu.brook/Documents/Brook/Work/Server/Python/realmServer/venv/lib/python3.6/site-packages/pymysql/connections.py", line 1340, in read
    first_packet = self.connection._read_packet()
  File "/Users/chliu.brook/Documents/Brook/Work/Server/Python/realmServer/venv/lib/python3.6/site-packages/pymysql/connections.py", line 1014, in _read_packet
    packet.check_error()
  File "/Users/chliu.brook/Documents/Brook/Work/Server/Python/realmServer/venv/lib/python3.6/site-packages/pymysql/connections.py", line 393, in check_error
    err.raise_mysql_exception(self._data)
  File "/Users/chliu.brook/Documents/Brook/Work/Server/Python/realmServer/venv/lib/python3.6/site-packages/pymysql/err.py", line 107, in raise_mysql_exception
    raise errorclass(errno, errval)
sqlalchemy.exc.ProgrammingError: (pymysql.err.ProgrammingError) (1064, "You have an error in your SQL syntax; check the manual that corresponds to your MySQL server version for the right syntax to use near 'userCode = 'UR20180102210820239320FSFA'' at line 1") [SQL: 'select userCode,userName from TM_USER where 1=1and userCode = %(userCode)s'] [parameters: {'userCode': 'UR20180102210820239320FSFA'}]
Exception on /user/F1005 [POST]
Traceback (most recent call last):
  File "/Users/chliu.brook/Documents/Brook/Work/Server/Python/realmServer/venv/lib/python3.6/site-packages/flask/app.py", line 1982, in wsgi_app
    response = self.full_dispatch_request()
  File "/Users/chliu.brook/Documents/Brook/Work/Server/Python/realmServer/venv/lib/python3.6/site-packages/flask/app.py", line 1615, in full_dispatch_request
    return self.finalize_request(rv)
  File "/Users/chliu.brook/Documents/Brook/Work/Server/Python/realmServer/venv/lib/python3.6/site-packages/flask/app.py", line 1630, in finalize_request
    response = self.make_response(rv)
  File "/Users/chliu.brook/Documents/Brook/Work/Server/Python/realmServer/venv/lib/python3.6/site-packages/flask/app.py", line 1740, in make_response
    rv = self.response_class.force_type(rv, request.environ)
  File "/Users/chliu.brook/Documents/Brook/Work/Server/Python/realmServer/venv/lib/python3.6/site-packages/werkzeug/wrappers.py", line 885, in force_type
    response = BaseResponse(*_run_wsgi_app(response, environ))
  File "/Users/chliu.brook/Documents/Brook/Work/Server/Python/realmServer/venv/lib/python3.6/site-packages/werkzeug/wrappers.py", line 57, in _run_wsgi_app
    return _run_wsgi_app(*args)
  File "/Users/chliu.brook/Documents/Brook/Work/Server/Python/realmServer/venv/lib/python3.6/site-packages/werkzeug/test.py", line 884, in run_wsgi_app
    app_rv = app(environ, start_response)
TypeError: 'DataResopnse' object is not callable
